Exception on / [GET]
Traceback (most recent call last):
  File "/home/subrata/.local/lib/python3.5/site-packages/flask/app.py", line 1817, in wsgi_app
    response = self.full_dispatch_request()
  File "/home/subrata/.local/lib/python3.5/site-packages/flask/app.py", line 1477, in full_dispatch_request
    rv = self.handle_user_exception(e)
  File "/home/subrata/.local/lib/python3.5/site-packages/flask/app.py", line 1381, in handle_user_exception
    reraise(exc_type, exc_value, tb)
  File "/home/subrata/.local/lib/python3.5/site-packages/flask/_compat.py", line 33, in reraise
    raise value
  File "/home/subrata/.local/lib/python3.5/site-packages/flask/app.py", line 1475, in full_dispatch_request
    rv = self.dispatch_request()
  File "/home/subrata/.local/lib/python3.5/site-packages/flask/app.py", line 1461, in dispatch_request
    return self.view_functions[rule.endpoint](**req.view_args)
TypeError: allowed_file() missing 1 required positional argument: 'filename'
